Workbook

Sheet Movies
A1: Movie Name | B1: Release Date | C1: Genre | D1: IMDB | E1: Rotten | F1: Final Score | G1: Protagonist | H1: Antagonist | I1: Soundtrack | J1: Set Design | K1: Plot | L1: Ending | M1: Runtime | N1: Date Watched | O1: Style | P1: Show or Movie | Q1: Diff IMDB | R1: Diff Rotten
A2: Dune: Part Two | B2: 01 Mar 2024 | C2: Action, Adventure, Drama | D2: 8.5 | E2: 0.92 | F2: 9.8333333 | G2: 9.8 | H2: 9.6 | I2: 10 | J2: 10 | K2: 9.8 | L2: 9.8 | M2: 166 min | N2: 45625 | O2: Live Action | P2: Movie
A3: Interstellar | B3: 07 Nov 2014 | C3: Adventure, Drama, Sci-Fi | D3: 8.7 | E3: 0.73 | F3: 9.8166667 | G3: 10 | H3: 9.5 | I3: 10 | J3: 10 | K3: 9.7 | L3: 9.7 | M3: 169 min | N3: 45608 | O3: Live Action | P3: Movie
A4: Gladiator | B4: 05 May 2000 | C4: Action, Adventure, Drama | D4: 8.5 | E4: 0.8 | F4: 9.6333333 | G4: 10 | H4: 9.1 | I4: 9.8 | J4: 9.2 | K4: 9.7 | L4: 10 | M4: 155 min | N4: 45627 | O4: Live Action | P4: Movie
A5: Dune | B5: 14 Dec 1984 | C5: Action, Adventure, Sci-Fi | D5: 6.3 | E5: 0.36 | F5: 9.6166667 | G5: 9.5 | H5: 9.4 | I5: 10 | J5: 9.9 | K5: 9.5 | L5: 9.4 | M5: 137 min | N5: 45625 | O5: Live Action | P5: Movie
A6: The Prestige | B6: 20 Oct 2006 | C6: Drama, Mystery, Sci-Fi | D6: 8.5 | E6: 0.77 | F6: 9.5333333 | G6: 9.4 | H6: 9.4 | I6: 9.3 | J6: 9.2 | K6: 9.9 | L6: 10 | M6: 130 min | N6: 45808 | O6: Live Action | P6: Movie
A7: Se7en | B7: 22 Sep 1995 | C7: Crime, Drama, Mystery | D7: 8.6 | E7: 0.84 | F7: 9.5166667 | G7: 9.3 | H7: 10 | I7: 8.5 | J7: 9.3 | K7: 10 | L7: 10 | M7: 127 min | N7: 46042 | O7: Live Action | P7: Movie
A8: 1917 | B8: 10 Jan 2020 | C8: Action, Drama, War | D8: 8.2 | E8: 0.88 | F8: 9.45 | G8: 9.2 | H8: 8.9 | I8: 9.7 | J8: 9.7 | K8: 9.8 | L8: 9.4 | M8: 119 min | N8: 45628 | O8: Live Action | P8: Movie
A9: Whiplash | B9: 15 Oct 2014 | C9: Drama, Music | D9: 8.5 | E9: 0.94 | F9: 9.4333333 | G9: 9.4 | H9: 10 | I9: 9.4 | J9: 8.5 | K9: 9.4 | L9: 9.9 | M9: 106 min | N9: 45858 | O9: Live Action | P9: Movie
A10: Inception | B10: 16 Jul 2010 | C10: Action, Adventure, Sci-Fi | D10: 8.8 | E10: 0.87 | F10: 9.4 | G10: 9 | H10: 8.7 | I10: 10 | J10: 9.3 | K10: 9.7 | L10: 9.7 | M10: 148 min | N10: 45608 | O10: Live Action | P10: Movie
A11: Edge Of Tomorrow | B11: 06 Jun 2014 | C11: Action, Adventure, Sci-Fi | D11: 7.9 | E11: 0.91 | F11: 9.35 | G11: 8.9 | H11: 9.5 | I11: 8.4 | J11: 9.5 | K11: 9.9 | L11: 9.9 | M11: 113 min | N11: 45628 | O11: Live Action | P11: Movie
A12: The Martian | B12: 02 Oct 2015 | C12: Adventure, Drama, Sci-Fi | D12: 8 | E12: 0.91 | F12: 9.2666667 | G12: 9.3 | H12: 9.2 | I12: 9.5 | J12: 9.2 | K12: 9.3 | L12: 9.1 | M12: 144 min | N12: 45874 | O12: Live Action | P12: Movie
A13: Gladiator II | B13: 22 Nov 2024 | C13: Action, Adventure, Drama | D13: 6.5 | E13: 0.7 | F13: 9.2666667 | G13: 9.3 | H13: 8.7 | I13: 9.3 | J13: 9.6 | K13: 9.6 | L13: 9.1 | M13: 148 min | N13: 45627 | O13: Live Action | P13: Movie
... A21: Spider-Man: No Way Home | B21: 17 Dec 2021 | C21: Action, Adventure, Fantasy | D21: 8.2 | E21: 0.93 | F21: 9.2 | G21: 9 | H21: 9 | I21: 8.7 | J21: 9.1 | K21: 9.5 | L21: 9.9 | M21: 148 min | N21: 45628 | O21: Live Action | P21: Movie
A22: Project Hail Mary | B22: 20 Mar 2026 | C22: Adventure, Comedy, Drama | D22: 8.3 | E22: 0.94 | F22: 9.2 | G22: 9.1 | H22: 8.5 | I22: 9.4 | J22: 9.8 | K22: 9.3 | L22: 9.1 | M22: 156 min | N22: 46187
A23: Oppenheimer | B23: 21 Jul 2023 | C23: Biography, Drama, History | D23: 8.3 | E23: 0.93 | F23: 9.1333333 | G23: 9.3 | H23: 8.8 | I23: 9.7 | J23: 8.9 | K23: 9.3 | L23: 8.8 | M23: 180 min | N23: 45628 | O23: Live Action | P23: Movie
A24: Avengers: Infinity War | B24: 27 Apr 2018 | C24: Action, Adventure, Sci-Fi | D24: 8.4 | E24: 0.85 | F24: 9.05 | G24: 9.4 | H24: 9.5 | I24: 9.3 | J24: 9.1 | K24: 8.5 | L24: 8.5 | M24: 149 min | N24: 45628 | O24: Live Action | P24: Movie
A25: The Lord of the Rings: The Two Towers | B25: 18 Dec 2002 | C25: Adventure, Drama, Fantasy | D25: 8.8 | E25: 0.95 | F25: 9.0166667 | G25: 9.4 | H25: 9.3 | I25: 9.1 | J25: 9 | K25: 8.7 | L25: 8.6 | M25: 179 min | N25: 45948 | O25: Live Action | P25: Movie
A26: Sinners | B26: 18 Apr 2025 | C26: Action, Drama, Horror | D26: 7.6 | E26: 0.97 | F26: 9.0166667 | G26: 8.8 | H26: 8.8 | I26: 8.9 | J26: 8.2 | K26: 9.6 | L26: 9.8 | M26: 137 min | N26: 45765 | O26: Live Action | P26: Movie
A27: Only the Brave | B27: 20 Oct 2017 | C27: Action, Biography, Drama | D27: 7.6 | E27: 0.87 | F27: 9 | G27: 8.7 | H27: 8.7 | I27: 8.8 | J27: 8.7 | K27: 9.5 | L27: 9.6 | M27: 134 min | N27: 45874 | O27: Live Action | P27: Movie
A28: Vesper | B28: 30 Sep 2022 | C28: Adventure, Drama, Sci-Fi | D28: 6 | E28: 0.91 | F28: 9 | G28: 8.9 | H28: 9.4 | I28: 8.7 | J28: 10 | K28: 8.3 | L28: 8.7 | M28: 114 min | N28: 46086 | O28: Live Action | P28: Movie
A29: How To Train Your Dragon 2 | B29: 13 Jun 2014 | C29: Animation, Action, Adventure | D29: 7.8 | E29: 0.92 | F29: 9 | G29: 9.2 | H29: 9.1 | I29: 9.5 | J29: 8.9 | K29: 8.4 | L29: 8.9 | M29: 102 min | N29: 45925 | O29: Live Action | P29: Movie
A30: Tenet | B30: 03 Sep 2020 | C30: Action, Sci-Fi, Thriller | D30: 7.3 | E30: 0.7 | F30: 8.9833333 | G30: 8.4 | H30: 7.9 | I30: 9.2 | J30: 9.6 | K30: 9.7 | L30: 9.1 | M30: 150 min | N30: 45608 | O30: Live Action | P30: Movie
A31: Before Sunset | B31: 30 Jul 2004 | C31: Drama, Romance | D31: 8.1 | E31: 0.94 | F31: 8.9666667 | G31: 9.5 | H31: 9.3 | I31: 8 | J31: 7.5 | K31: 9.8 | L31: 9.7 | M31: 80 min | N31: 46245 | O31: Live Action | P31: Movie
A32: Sicario | B32: 02 Oct 2015 | C32: Action, Crime, Drama | D32: 7.7 | E32: 0.92 | F32: 8.9 | G32: 8.9 | H32: 9.2 | I32: 8.4 | J32: 8.7 | K32: 9.3 | L32: 8.9 | M32: 121 min | N32: 45863 | O32: Live Action | P32: Movie
A33: The Lord of the Rings: The Fellowship of the Ring | B33: 19 Dec 2001 | C33: Adventure, Drama, Fantasy | D33: 8.9 | E33: 0.92 | F33: 8.9 | G33: 9.3 | H33: 8.6 | I33: 9.9 | J33: 8.8 | K33: 8.3 | L33: 8.5 | M33: 178 min | N33: 45948 | O33: Live Action | P33: Movie
A34: Memories of Murder | B34: 02 May 2003 | C34: Crime, Drama, Mystery | D34: 8.1 | F34: 8.8833333 | G34: 8.7 | H34: 8.6 | I34: 8.5 | J34: 7.9 | K34: 9.6 | L34: 10 | M34: 132 min | N34: 45875 | O34: Live Action | P34: Movie
A35: The Accountant | B35: 14 Oct 2016 | C35: Action, Crime, Drama | D35: 7.3 | E35: 0.53 | F35: 8.8833333 | G35: 9.5 | H35: 9.2 | I35: 7.7 | J35: 8.6 | K35: 9.4 | L35: 8.9 | M35: 128 min | N35: 45863 | O35: Live Action | P35: Movie
A36: Saving Private Ryan | B36: 24 Jul 1998 | C36: Drama, War | D36: 8.6 | E36: 0.94 | F36: 8.85 | G36: 8.8 | H36: 8.8 | I36: 8.8 | J36: 8.8 | K36: 9.3 | L36: 8.6 | M36: 169 min | N36: 45646 | O36: Live Action | P36: Movie
A37: Good Will Hunting | B37: 09 Jan 1998 | C37: Drama, Romance | D37: 8.3 | E37: 0.97 | F37: 8.8333333 | G37: 9.7 | H37: 9.7 | I37: 7.1 | J37: 7.2 | K37: 9.6 | L37: 9.7 | M37: 126 min | N37: 45874 | O37: Live Action | P37: Movie
A38: Pacific Rim | B38: 12 Jul 2013 | C38: Action, Adventure, Sci-Fi | D38: 6.9 | E38: 0.72 | F38: 8.8333333 | G38: 8.8 | H38: 8.8 | I38: 8.7 | J38: 9.4 | K38: 9.2 | L38: 8.1 | M38: 131 min | N38: 45625 | O38: Live Action | P38: Movie
A39: Her | B39: 10 Jan 2014 | C39: Drama, Romance, Sci-Fi | D39: 8 | E39: 0.95 | F39: 8.8 | G39: 8.8 | H39: 9.3 | I39: 7.5 | J39: 8.9 | K39: 9 | L39: 9.3 | M39: 126 min | N39: 45997 | O39: Live Action | P39: Movie
A40: Blade Runner 2049 | B40: 06 Oct 2017 | C40: Action, Drama, Mystery | D40: 8 | E40: 0.88 | F40: 8.8 | G40: 8.5 | H40: 8.7 | I40: 7.8 | J40: 9.1 | K40: 8.9 | L40: 9.8 | M40: 164 min | N40: 45747 | O40: Live Action | P40: Movie
A41: The Imitation Game | B41: 25 Dec 2014 | C41: Biography, Drama, Thriller | D41: 8 | E41: 0.9 | F41: 8.7666667 | G41: 8.9 | H41: 8.1 | I41: 9.2 | J41: 8.4 | K41: 9.1 | L41: 8.9 | M41: 114 min | N41: 45874 | O41: Live Action | P41: Movie
A42: Deadpool & Wolverine | B42: 26 Jul 2024 | C42: Action, Adventure, Comedy | D42: 7.5 | E42: 0.78 | F42: 8.75 | G42: 8.9 | H42: 7.5 | I42: 9.3 | J42: 8.7 | K42: 8.9 | L42: 9.2 | M42: 128 min | N42: 45625 | O42: Live Action | P42: Movie
A43: Everything Everywhere All At Once | B43: 08 Apr 2022 | C43: Action, Adventure, Comedy | D43: 7.8 | E43: 0.94 | F43: 8.7333333 | G43: 8.7 | H43: 8.8 | I43: 7.7 | J43: 9.1 | K43: 8.9 | L43: 9.2 | M43: 139 min | N43: 45874 | O43: Live Action | P43: Movie
A44: One Battle After Another | B44: 26 Sep 2025 | C44: Action, Crime, Drama | D44: 7.7 | E44: 0.94 | F44: 8.7333333 | G44: 8.9 | H44: 9.3 | I44: 9 | J44: 8.6 | K44: 8.7 | L44: 7.9 | M44: 161 min | N44: 46153 | O44: Live Action | P44: Movie
A45: Spectral | B45: 09 Dec 2016 | C45: Action, Adventure, Sci-Fi | D45: 6.3 | E45: 0.78 | F45: 8.6833333 | G45: 7.2 | H45: 9.4 | I45: 8.2 | J45: 8.8 | K45: 9.3 | L45: 9.2 | M45: 107 min | N45: 45689 | O45: Live Action | P45: Movie
A46: Green Book | B46: 16 Nov 2018 | C46: Biography, Comedy, Drama | D46: 8.2 | E46: 0.77 | F46: 8.6833333 | G46: 8.7 | H46: 9.1 | I46: 8.5 | J46: 8.2 | K46: 8.8 | L46: 8.8 | M46: 130 min | N46: 45874 | O46: Live Action | P46: Movie
A47: The Thin Red Line | B47: 15 Jan 1999 | C47: Drama, History, War | D47: 7.6 | E47: 0.8 | F47: 8.6833333 | G47: 8.8 | H47: 7.9 | I47: 9.6 | J47: 9.2 | K47: 7.8 | L47: 8.8 | M47: 170 min | N47: 46159 | O47: Live Action | P47: Movie
...

Sheet Dashboard
D4: Top 10 Movies | G4: Total Movies Watched
D6: =CONCATENATE("1. ", Backend!O3) -> 1. Dune: Part Two | E6: =Backend!P3 -> 9.8333333 | G6: =COUNTA(Movies!D:D) -> 309
D7: =CONCATENATE("2. ", Backend!O4) -> 2. Interstellar | E7: =Backend!P4 -> 9.8166667
D8: =CONCATENATE("3. ", Backend!O5) -> 3. Gladiator | E8: =Backend!P5 -> 9.6333333
D9: =CONCATENATE("4. ", Backend!O6) -> 4. Dune | E9: =Backend!P6 -> 9.6166667
D10: =CONCATENATE("5. ", Backend!O7) -> 5. The Prestige | E10: =Backend!P7 -> 9.5333333 | G10: Total Hours Watched
D11: =CONCATENATE("6. ", Backend!O8) -> 6. Se7en | E11: =Backend!P8 -> 9.5166667
D12: =CONCATENATE("7. ", Backend!O9) -> 7. 1917 | E12: =Backend!P9 -> 9.45 | G12: =IFERROR(__xludf.DUMMYFUNCTION("SUMPRODUCT((Movies!D2:D1000<>"""")*(ISNUMBER(VALUE(REGEXREPLACE(Movies!M2:M1000, "" min"", """"))))*(IFERROR(VALUE(REGEXREPLACE(Movies!M2:M1000, "" min"", """")), 0))) / 60"),627.1166666666667) -> 627.11667
D13: =CONCATENATE("8. ", Backend!O10) -> 8. Whiplash | E13: =Backend!P10 -> 9.4333333
D14: =CONCATENATE("9. ", Backend!O11) -> 9. Inception | E14: =Backend!P11 -> 9.4
D15: =CONCATENATE("10. ", Backend!O12) -> 10. Edge Of Tomorrow | E15: =Backend!P12 -> 9.35

Sheet Backend
G1: Genre Breakdown | J1: Grading Scale | O1: Top 10 | S1: Movies over time | W1: Grades over time
B2: =Movies!C2 -> Action, Adventure, Drama | C2: =IFERROR(__xludf.DUMMYFUNCTION("ARRAYFORMULA(TRIM(SPLIT(B2, "",""))) "),"Action") -> Action | D2: =IFERROR(__xludf.DUMMYFUNCTION("""COMPUTED_VALUE"""),"Adventure") -> Adventure | E2: =IFERROR(__xludf.DUMMYFUNCTION("""COMPUTED_VALUE"""),"Drama") -> Drama | G2: =IFERROR(__xludf.DUMMYFUNCTION("UNIQUE(FLATTEN(C2:E1000))"),"Action") -> Action | H2: =COUNTIF(C2:E1000, G2) -> 171 | J2: 0.1 | K2: =COUNTIFS(Movies[Final Score], "<" & J2, Movies[Final Score], ">=" & J1) -> 0 | L2: 1 | M2: =COUNTIFS(Movies[Final Score], "<" & L3, Movies[Final Score], ">=" & L2) -> 1 | S2: =IFERROR(__xludf.DUMMYFUNCTION("SORT(UNIQUE(QUERY(Movies!N2:N1000, ""select N where N is not null"", 0))) "),45604.0) -> 45604 | T2: =COUNTIF(Movies!N:N, S2) -> 1 | U2: =SUM($T$2:T2) -> 1 | W2: =IFERROR(__xludf.DUMMYFUNCTION("SORT(UNIQUE(QUERY(ARRAYFORMULA(DATEVALUE(Movies!B2:B1000)),""select Col1 where Col1 is not null"",0))) "),23911.0) -> 23911 | X2: =IFERROR(__xludf.DUMMYFUNCTION("FILTER( Movies!F2:F1000, DATEVALUE(Movies!B2:B1000) = W2 ) "),7.916666666666667) -> 7.9166667
B3: =Movies!C3 -> Adventure, Drama, Sci-Fi | C3: =IFERROR(__xludf.DUMMYFUNCTION("ARRAYFORMULA(TRIM(SPLIT(B3, "",""))) "),"Adventure") -> Adventure | D3: =IFERROR(__xludf.DUMMYFUNCTION("""COMPUTED_VALUE"""),"Drama") -> Drama | E3: =IFERROR(__xludf.DUMMYFUNCTION("""COMPUTED_VALUE"""),"Sci-Fi") -> Sci-Fi | G3: =IFERROR(__xludf.DUMMYFUNCTION("""COMPUTED_VALUE"""),"Adventure") -> Adventure | H3: =COUNTIF(C3:E1001, G3) -> 132 | J3: 0.2 | K3: =COUNTIFS(Movies[Final Score], "<" & J3, Movies[Final Score], ">=" & J2) -> 0 | L3: 2 | M3: =COUNTIFS(Movies[Final Score], "<" & L4, Movies[Final Score], ">=" & L3) -> 1 | O3: =IFERROR(__xludf.DUMMYFUNCTION("SORTN(Movies!A2:A1000, 10, 0, 6, FALSE)"),"Dune: Part Two") -> Dune: Part Two | P3: =IFERROR(__xludf.DUMMYFUNCTION("SORTN(Movies!F2:F1000, 10, 0, 6, FALSE)"),9.833333333333334) -> 9.8333333 | S3: =IFERROR(__xludf.DUMMYFUNCTION("""COMPUTED_VALUE"""),45608.0) -> 45608 | T3: =COUNTIF(Movies!N:N, S3) -> 10 | U3: =SUM($T$2:T3) -> 11 | W3: =IFERROR(__xludf.DUMMYFUNCTION("""COMPUTED_VALUE"""),26331.0) -> 26331 | X3: =IFERROR(__xludf.DUMMYFUNCTION("FILTER( Movies!F3:F1000, DATEVALUE(Movies!B3:B1000) = W3 ) "),7.233333333333333) -> 7.2333333
B4: =Movies!C4 -> Action, Adventure, Drama | C4: =IFERROR(__xludf.DUMMYFUNCTION("ARRAYFORMULA(TRIM(SPLIT(B4, "",""))) "),"Action") -> Action | D4: =IFERROR(__xludf.DUMMYFUNCTION("""COMPUTED_VALUE"""),"Adventure") -> Adventure | E4: =IFERROR(__xludf.DUMMYFUNCTION("""COMPUTED_VALUE"""),"Drama") -> Drama | G4: =IFERROR(__xludf.DUMMYFUNCTION("""COMPUTED_VALUE"""),"Drama") -> Drama | H4: =COUNTIF(C4:E1002, G4) -> 105 | J4: 0.3 | K4: =COUNTIFS(Movies[Final Score], "<" & J4, Movies[Final Score], ">=" & J3) -> 0 | L4: 3 | M4: =COUNTIFS(Movies[Final Score], "<" & L5, Movies[Final Score], ">=" & L4) -> 2 | O4: =IFERROR(__xludf.DUMMYFUNCTION("""COMPUTED_VALUE"""),"Interstellar") -> Interstellar | P4: =IFERROR(__xludf.DUMMYFUNCTION("""COMPUTED_VALUE"""),9.816666666666668) -> 9.8166667 | S4: =IFERROR(__xludf.DUMMYFUNCTION("""COMPUTED_VALUE"""),45610.0) -> 45610 | T4: =COUNTIF(Movies!N:N, S4) -> 1 | U4: =SUM($T$2:T4) -> 12 | W4: =IFERROR(__xludf.DUMMYFUNCTION("""COMPUTED_VALUE"""),28336.0) -> 28336 | X4: =IFERROR(__xludf.DUMMYFUNCTION("FILTER( Movies!F4:F1000, DATEVALUE(Movies!B4:B1000) = W4 ) "),3.4166666666666665) -> 3.4166667
B5: =Movies!C5 -> Action, Adventure, Sci-Fi | C5: =IFERROR(__xludf.DUMMYFUNCTION("ARRAYFORMULA(TRIM(SPLIT(B5, "",""))) "),"Action") -> Action | D5: =IFERROR(__xludf.DUMMYFUNCTION("""COMPUTED_VALUE"""),"Adventure") -> Adventure | E5: =IFERROR(__xludf.DUMMYFUNCTION("""COMPUTED_VALUE"""),"Sci-Fi") -> Sci-Fi | G5: =IFERROR(__xludf.DUMMYFUNCTION("""COMPUTED_VALUE"""),"Sci-Fi") -> Sci-Fi | H5: =COUNTIF(C5:E1003, G5) -> 75 | J5: 0.4 | K5: =COUNTIFS(Movies[Final Score], "<" & J5, Movies[Final Score], ">=" & J4) -> 0 | L5: 4 | M5: =COUNTIFS(Movies[Final Score], "<" & L6, Movies[Final Score], ">=" & L5) -> 10 | O5: =IFERROR(__xludf.DUMMYFUNCTION("""COMPUTED_VALUE"""),"Gladiator") -> Gladiator | P5: =IFERROR(__xludf.DUMMYFUNCTION("""COMPUTED_VALUE"""),9.633333333333333) -> 9.6333333 | S5: =IFERROR(__xludf.DUMMYFUNCTION("""COMPUTED_VALUE"""),45620.0) -> 45620 | T5: =COUNTIF(Movies!N:N, S5) -> 1 | U5: =SUM($T$2:T5) -> 13 | W5: =IFERROR(__xludf.DUMMYFUNCTION("""COMPUTED_VALUE"""),28529.0) -> 28529 | X5: =IFERROR(__xludf.DUMMYFUNCTION("FILTER( Movies!F5:F1000, DATEVALUE(Movies!B5:B1000) = W5 ) "),8.033333333333333) -> 8.0333333
B6: =Movies!C6 -> Drama, Mystery, Sci-Fi | C6: =IFERROR(__xludf.DUMMYFUNCTION("ARRAYFORMULA(TRIM(SPLIT(B6, "",""))) "),"Drama") -> Drama | D6: =IFERROR(__xludf.DUMMYFUNCTION("""COMPUTED_VALUE"""),"Mystery") -> Mystery | E6: =IFERROR(__xludf.DUMMYFUNCTION("""COMPUTED_VALUE"""),"Sci-Fi") -> Sci-Fi | G6: =IFERROR(__xludf.DUMMYFUNCTION("""COMPUTED_VALUE"""),"Mystery") -> Mystery | H6: =COUNTIF(C6:E1004, G6) -> 24 | J6: 0.5 | K6: =COUNTIFS(Movies[Final Score], "<" & J6, Movies[Final Score], ">=" & J5) -> 0 | L6: 5 | M6: =COUNTIFS(Movies[Final Score], "<" & L7, Movies[Final Score], ">=" & L6) -> 30 | O6: =IFERROR(__xludf.DUMMYFUNCTION("""COMPUTED_VALUE"""),"Dune") -> Dune | P6: =IFERROR(__xludf.DUMMYFUNCTION("""COMPUTED_VALUE"""),9.616666666666665) -> 9.6166667 | S6: =IFERROR(__xludf.DUMMYFUNCTION("""COMPUTED_VALUE"""),45625.0) -> 45625 | T6: =COUNTIF(Movies!N:N, S6) -> 14 | U6: =SUM($T$2:T6) -> 27 | W6: =IFERROR(__xludf.DUMMYFUNCTION("""COMPUTED_VALUE"""),30127.0) -> 30127 | X6: =IFERROR(__xludf.DUMMYFUNCTION("FILTER( Movies!F6:F1000, DATEVALUE(Movies!B6:B1000) = W6 ) "),7.233333333333333) -> 7.2333333
B7: =Movies!C7 -> Crime, Drama, Mystery | C7: =IFERROR(__xludf.DUMMYFUNCTION("ARRAYFORMULA(TRIM(SPLIT(B7, "",""))) "),"Crime") -> Crime | D7: =IFERROR(__xludf.DUMMYFUNCTION("""COMPUTED_VALUE"""),"Drama") -> Drama | E7: =IFERROR(__xludf.DUMMYFUNCTION("""COMPUTED_VALUE"""),"Mystery") -> Mystery | G7: =IFERROR(__xludf.DUMMYFUNCTION("""COMPUTED_VALUE"""),"Crime") -> Crime | H7: =COUNTIF(C7:E1005, G7) -> 40 | J7: 0.6 | K7: =COUNTIFS(Movies[Final Score], "<" & J7, Movies[Final Score], ">=" & J6) -> 0 | L7: 6 | M7: =COUNTIFS(Movies[Final Score], "<" & L8, Movies[Final Score], ">=" & L7) -> 64 | O7: =IFERROR(__xludf.DUMMYFUNCTION("""COMPUTED_VALUE"""),"The Prestige") -> The Prestige | P7: =IFERROR(__xludf.DUMMYFUNCTION("""COMPUTED_VALUE"""),9.533333333333333) -> 9.5333333 | S7: =IFERROR(__xludf.DUMMYFUNCTION("""COMPUTED_VALUE"""),45626.0) -> 45626 | T7: =COUNTIF(Movies!N:N, S7) -> 1 | U7: =SUM($T$2:T7) -> 28 | W7: =IFERROR(__xludf.DUMMYFUNCTION("""COMPUTED_VALUE"""),31030.0) -> 31030 | X7: =IFERROR(__xludf.DUMMYFUNCTION("FILTER( Movies!F7:F1000, DATEVALUE(Movies!B7:B1000) = W7 ) "),"#N/A") -> #N/A
B8: =Movies!C8 -> Action, Drama, War | C8: =IFERROR(__xludf.DUMMYFUNCTION("ARRAYFORMULA(TRIM(SPLIT(B8, "",""))) "),"Action") -> Action | D8: =IFERROR(__xludf.DUMMYFUNCTION("""COMPUTED_VALUE"""),"Drama") -> Drama | E8: =IFERROR(__xludf.DUMMYFUNCTION("""COMPUTED_VALUE"""),"War") -> War | G8: =IFERROR(__xludf.DUMMYFUNCTION("""COMPUTED_VALUE"""),"War") -> War | H8: =COUNTIF(C8:E1006, G8) -> 6 | J8: 0.7 | K8: =COUNTIFS(Movies[Final Score], "<" & J8, Movies[Final Score], ">=" & J7) -> 0 | L8: 7 | M8: =COUNTIFS(Movies[Final Score], "<" & L9, Movies[Final Score], ">=" & L8) -> 94 | O8: =IFERROR(__xludf.DUMMYFUNCTION("""COMPUTED_VALUE"""),"Se7en") -> Se7en | P8: =IFERROR(__xludf.DUMMYFUNCTION("""COMPUTED_VALUE"""),9.516666666666667) -> 9.5166667 | S8: =IFERROR(__xludf.DUMMYFUNCTION("""COMPUTED_VALUE"""),45627.0) -> 45627 | T8: =COUNTIF(Movies!N:N, S8) -> 4 | U8: =SUM($T$2:T8) -> 32 | W8: =IFERROR(__xludf.DUMMYFUNCTION("""COMPUTED_VALUE"""),33095.0) -> 33095 | X8: =IFERROR(__xludf.DUMMYFUNCTION("FILTER( Movies!F8:F1000, DATEVALUE(Movies!B8:B1000) = W8 ) "),5.466666666666666) -> 5.4666667
B9: =Movies!C9 -> Drama, Music | C9: =IFERROR(__xludf.DUMMYFUNCTION("ARRAYFORMULA(TRIM(SPLIT(B9, "",""))) "),"Drama") -> Drama | D9: =IFERROR(__xludf.DUMMYFUNCTION("""COMPUTED_VALUE"""),"Music") -> Music | G9: =IFERROR(__xludf.DUMMYFUNCTION("""COMPUTED_VALUE"""),"Music") -> Music | H9: =COUNTIF(C9:E1007, G9) -> 3 | J9: 0.8 | K9: =COUNTIFS(Movies[Final Score], "<" & J9, Movies[Final Score], ">=" & J8) -> 1 | L9: 8 | M9: =COUNTIFS(Movies[Final Score], "<" & L10, Movies[Final Score], ">=" & L9) -> 79 | O9: =IFERROR(__xludf.DUMMYFUNCTION("""COMPUTED_VALUE"""),"1917") -> 1917 | P9: =IFERROR(__xludf.DUMMYFUNCTION("""COMPUTED_VALUE"""),9.45) -> 9.45 | S9: =IFERROR(__xludf.DUMMYFUNCTION("""COMPUTED_VALUE"""),45628.0) -> 45628 | T9: =COUNTIF(Movies!N:N, S9) -> 23 | U9: =SUM($T$2:T9) -> 55 | W9: =IFERROR(__xludf.DUMMYFUNCTION("""COMPUTED_VALUE"""),34131.0) -> 34131 | X9: =IFERROR(__xludf.DUMMYFUNCTION("FILTER( Movies!F9:F1000, DATEVALUE(Movies!B9:B1000) = W9 ) "),8.066666666666668) -> 8.0666667
B10: =Movies!C10 -> Action, Adventure, Sci-Fi | C10: =IFERROR(__xludf.DUMMYFUNCTION("ARRAYFORMULA(TRIM(SPLIT(B10, "",""))) "),"Action") -> Action | D10: =IFERROR(__xludf.DUMMYFUNCTION("""COMPUTED_VALUE"""),"Adventure") -> Adventure | E10: =IFERROR(__xludf.DUMMYFUNCTION("""COMPUTED_VALUE"""),"Sci-Fi") -> Sci-Fi | H10: =COUNTIF(C10:E1008, G10) -> 0 | J10: 0.9 | K10: =COUNTIFS(Movies[Final Score], "<" & J10, Movies[Final Score], ">=" & J9) -> 0 | L10: 9 | M10: =COUNTIFS(Movies[Final Score], "<" & L11, Movies[Final Score], ">=" & L10) -> 28 | O10: =IFERROR(__xludf.DUMMYFUNCTION("""COMPUTED_VALUE"""),"Whiplash") -> Whiplash | P10: =IFERROR(__xludf.DUMMYFUNCTION("""COMPUTED_VALUE"""),9.433333333333332) -> 9.4333333 | S10: =IFERROR(__xludf.DUMMYFUNCTION("""COMPUTED_VALUE"""),45646.0) -> 45646 | T10: =COUNTIF(Movies!N:N, S10) -> 45 | U10: =SUM($T$2:T10) -> 100 | W10: =IFERROR(__xludf.DUMMYFUNCTION("""COMPUTED_VALUE"""),34285.0) -> 34285 | X10: =IFERROR(__xludf.DUMMYFUNCTION("FILTER( Movies!F10:F1000, DATEVALUE(Movies!B10:B1000) = W10 ) "),6.816666666666666) -> 6.8166667
B11: =Movies!C11 -> Action, Adventure, Sci-Fi | C11: =IFERROR(__xludf.DUMMYFUNCTION("ARRAYFORMULA(TRIM(SPLIT(B11, "",""))) "),"Action") -> Action | D11: =IFERROR(__xludf.DUMMYFUNCTION("""COMPUTED_VALUE"""),"Adventure") -> Adventure | E11: =IFERROR(__xludf.DUMMYFUNCTION("""COMPUTED_VALUE"""),"Sci-Fi") -> Sci-Fi | G11: =IFERROR(__xludf.DUMMYFUNCTION("""COMPUTED_VALUE"""),"Comedy") -> Comedy | H11: =COUNTIF(C11:E1009, G11) -> 52 | J11: 1 | K11: =COUNTIFS(Movies[Final Score], "<" & J11, Movies[Final Score], ">=" & J10) -> 0 | L11: 10 | M11: =COUNTIFS(Movies[Final Score], "<" & L12, Movies[Final Score], ">=" & L11) -> 0 | O11: =IFERROR(__xludf.DUMMYFUNCTION("""COMPUTED_VALUE"""),"Inception") -> Inception | P11: =IFERROR(__xludf.DUMMYFUNCTION("""COMPUTED_VALUE"""),9.4) -> 9.4 | S11: =IFERROR(__xludf.DUMMYFUNCTION("""COMPUTED_VALUE"""),45647.0) -> 45647 | T11: =COUNTIF(Movies!N:N, S11) -> 1 | U11: =SUM($T$2:T11) -> 101 | W11: =IFERROR(__xludf.DUMMYFUNCTION("""COMPUTED_VALUE"""),34521.0) -> 34521 | X11: =IFERROR(__xludf.DUMMYFUNCTION("FILTER( Movies!F11:F1000, DATEVALUE(Movies!B11:B1000) = W11 ) "),8.616666666666667) -> 8.6166667
B12: =Movies!C12 -> Adventure, Drama, Sci-Fi | C12: =IFERROR(__xludf.DUMMYFUNCTION("ARRAYFORMULA(TRIM(SPLIT(B12, "",""))) "),"Adventure") -> Adventure | D12: =IFERROR(__xludf.DUMMYFUNCTION("""COMPUTED_VALUE"""),"Drama") -> Drama | E12: =IFERROR(__xludf.DUMMYFUNCTION("""COMPUTED_VALUE"""),"Sci-Fi") -> Sci-Fi | G12: =IFERROR(__xludf.DUMMYFUNCTION("""COMPUTED_VALUE"""),"Western") -> Western | H12: =COUNTIF(C12:E1010, G12) -> 1 | J12: 1.1 | K12: =COUNTIFS(Movies[Final Score], "<" & J12, Movies[Final Score], ">=" & J11) -> 0 | O12: =IFERROR(__xludf.DUMMYFUNCTION("""COMPUTED_VALUE"""),"Edge Of Tomorrow") -> Edge Of Tomorrow | P12: =IFERROR(__xludf.DUMMYFUNCTION("""COMPUTED_VALUE"""),9.35) -> 9.35 | S12: =IFERROR(__xludf.DUMMYFUNCTION("""COMPUTED_VALUE"""),45649.0) -> 45649 | T12: =COUNTIF(Movies!N:N, S12) -> 2 | U12: =SUM($T$2:T12) -> 103 | W12: =IFERROR(__xludf.DUMMYFUNCTION("""COMPUTED_VALUE"""),34621.0) -> 34621 | X12: =IFERROR(__xludf.DUMMYFUNCTION("FILTER( Movies!F12:F1000, DATEVALUE(Movies!B12:B1000) = W12 ) "),6.283333333333334) -> 6.2833333
B13: =Movies!C13 -> Action, Adventure, Drama | C13: =IFERROR(__xludf.DUMMYFUNCTION("ARRAYFORMULA(TRIM(SPLIT(B13, "",""))) "),"Action") -> Action | D13: =IFERROR(__xludf.DUMMYFUNCTION("""COMPUTED_VALUE"""),"Adventure") -> Adventure | E13: =IFERROR(__xludf.DUMMYFUNCTION("""COMPUTED_VALUE"""),"Drama") -> Drama | G13: =IFERROR(__xludf.DUMMYFUNCTION("""COMPUTED_VALUE"""),"Fantasy") -> Fantasy | H13: =COUNTIF(C13:E1011, G13) -> 38 | J13: 1.2 | K13: =COUNTIFS(Movies[Final Score], "<" & J13, Movies[Final Score], ">=" & J12) -> 0 | S13: =IFERROR(__xludf.DUMMYFUNCTION("""COMPUTED_VALUE"""),45655.0) -> 45655 | T13: =COUNTIF(Movies!N:N, S13) -> 2 | U13: =SUM($T$2:T13) -> 105 | W13: =IFERROR(__xludf.DUMMYFUNCTION("""COMPUTED_VALUE"""),34726.0) -> 34726 | X13: =IFERROR(__xludf.DUMMYFUNCTION("FILTER( Movies!F13:F1000, DATEVALUE(Movies!B13:B1000) = W13 ) "),7.683333333333334) -> 7.6833333
B14: =Movies!C14 -> Comedy, Drama, Music | C14: =IFERROR(__xludf.DUMMYFUNCTION("ARRAYFORMULA(TRIM(SPLIT(B14, "",""))) "),"Comedy") -> Comedy | D14: =IFERROR(__xludf.DUMMYFUNCTION("""COMPUTED_VALUE"""),"Drama") -> Drama | E14: =IFERROR(__xludf.DUMMYFUNCTION("""COMPUTED_VALUE"""),"Music") -> Music | G14: =IFERROR(__xludf.DUMMYFUNCTION("""COMPUTED_VALUE"""),"Animation") -> Animation | H14: =COUNTIF(C14:E1012, G14) -> 18 | J14: 1.3 | K14: =COUNTIFS(Movies[Final Score], "<" & J14, Movies[Final Score], ">=" & J13) -> 0 | S14: =IFERROR(__xludf.DUMMYFUNCTION("""COMPUTED_VALUE"""),45661.0) -> 45661 | T14: =COUNTIF(Movies!N:N, S14) -> 1 | U14: =SUM($T$2:T14) -> 106 | W14: =IFERROR(__xludf.DUMMYFUNCTION("""COMPUTED_VALUE"""),34964.0) -> 34964 | X14: =IFERROR(__xludf.DUMMYFUNCTION("FILTER( Movies!F14:F1000, DATEVALUE(Movies!B14:B1000) = W14 ) "),"#N/A") -> #N/A
B15: =Movies!C15 -> Action, Drama, Western | C15: =IFERROR(__xludf.DUMMYFUNCTION("ARRAYFORMULA(TRIM(SPLIT(B15, "",""))) "),"Action") -> Action | D15: =IFERROR(__xludf.DUMMYFUNCTION("""COMPUTED_VALUE"""),"Drama") -> Drama | E15: =IFERROR(__xludf.DUMMYFUNCTION("""COMPUTED_VALUE"""),"Western") -> Western | G15: =IFERROR(__xludf.DUMMYFUNCTION("""COMPUTED_VALUE"""),"Thriller") -> Thriller | H15: =COUNTIF(C15:E1013, G15) -> 48 | J15: 1.4 | K15: =COUNTIFS(Movies[Final Score], "<" & J15, Movies[Final Score], ">=" & J14) -> 0 | S15: =IFERROR(__xludf.DUMMYFUNCTION("""COMPUTED_VALUE"""),45670.0) -> 45670 | T15: =COUNTIF(Movies!N:N, S15) -> 5 | U15: =SUM($T$2:T15) -> 111 | W15: =IFERROR(__xludf.DUMMYFUNCTION("""COMPUTED_VALUE"""),35720.0) -> 35720 | X15: =IFERROR(__xludf.DUMMYFUNCTION("FILTER( Movies!F15:F1000, DATEVALUE(Movies!B15:B1000) = W15 ) "),7.099999999999999) -> 7.1
B16: =Movies!C16 -> Action, Crime, Drama | C16: =IFERROR(__xludf.DUMMYFUNCTION("ARRAYFORMULA(TRIM(SPLIT(B16, "",""))) "),"Action") -> Action | D16: =IFERROR(__xludf.DUMMYFUNCTION("""COMPUTED_VALUE"""),"Crime") -> Crime | E16: =IFERROR(__xludf.DUMMYFUNCTION("""COMPUTED_VALUE"""),"Drama") -> Drama | G16: =IFERROR(__xludf.DUMMYFUNCTION("""COMPUTED_VALUE"""),"Biography") -> Biography | J16: 1.5 | K16: =COUNTIFS(Movies[Final Score], "<" & J16, Movies[Final Score], ">=" & J15) -> 0 | S16: =IFERROR(__xludf.DUMMYFUNCTION("""COMPUTED_VALUE"""),45676.0) -> 45676 | T16: =COUNTIF(Movies!N:N, S16) -> 3 | U16: =SUM($T$2:T16) -> 114 | W16: =IFERROR(__xludf.DUMMYFUNCTION("""COMPUTED_VALUE"""),35804.0) -> 35804 | X16: =IFERROR(__xludf.DUMMYFUNCTION("FILTER( Movies!F16:F1000, DATEVALUE(Movies!B16:B1000) = W16 ) "),8.833333333333334) -> 8.8333333
B17: =Movies!C17 -> Adventure, Drama, Fantasy | C17: =IFERROR(__xludf.DUMMYFUNCTION("ARRAYFORMULA(TRIM(SPLIT(B17, "",""))) "),"Adventure") -> Adventure | D17: =IFERROR(__xludf.DUMMYFUNCTION("""COMPUTED_VALUE"""),"Drama") -> Drama | E17: =IFERROR(__xludf.DUMMYFUNCTION("""COMPUTED_VALUE"""),"Fantasy") -> Fantasy | G17: =IFERROR(__xludf.DUMMYFUNCTION("""COMPUTED_VALUE"""),"History") -> History | H17: =COUNTIF(C17:E1000, G17) -> 6 | J17: 1.6 | K17: =COUNTIFS(Movies[Final Score], "<" & J17, Movies[Final Score], ">=" & J16) -> 1 | S17: =IFERROR(__xludf.DUMMYFUNCTION("""COMPUTED_VALUE"""),45682.0) -> 45682 | T17: =COUNTIF(Movies!N:N, S17) -> 1 | U17: =SUM($T$2:T17) -> 115 | W17: =IFERROR(__xludf.DUMMYFUNCTION("""COMPUTED_VALUE"""),35923.0) -> 35923 | X17: =IFERROR(__xludf.DUMMYFUNCTION("FILTER( Movies!F17:F1000, DATEVALUE(Movies!B17:B1000) = W17 ) "),8.15) -> 8.15
B18: =Movies!C18 -> Action, Adventure, Sci-Fi | C18: =IFERROR(__xludf.DUMMYFUNCTION("ARRAYFORMULA(TRIM(SPLIT(B18, "",""))) "),"Action") -> Action | D18: =IFERROR(__xludf.DUMMYFUNCTION("""COMPUTED_VALUE"""),"Adventure") -> Adventure | E18: =IFERROR(__xludf.DUMMYFUNCTION("""COMPUTED_VALUE"""),"Sci-Fi") -> Sci-Fi | G18: =IFERROR(__xludf.DUMMYFUNCTION("""COMPUTED_VALUE"""),"Horror") -> Horror | H18: =COUNTIF(C18:E1001, G18) -> 23 | J18: 1.7 | K18: =COUNTIFS(Movies[Final Score], "<" & J18, Movies[Final Score], ">=" & J17) -> 0 | S18: =IFERROR(__xludf.DUMMYFUNCTION("""COMPUTED_VALUE"""),45689.0) -> 45689 | T18: =COUNTIF(Movies!N:N, S18) -> 1 | U18: =SUM($T$2:T18) -> 116 | W18: =IFERROR(__xludf.DUMMYFUNCTION("""COMPUTED_VALUE"""),36000.0) -> 36000 | X18: =IFERROR(__xludf.DUMMYFUNCTION("FILTER( Movies!F18:F1000, DATEVALUE(Movies!B18:B1000) = W18 ) "),8.85) -> 8.85
B19: =Movies!C19 -> Animation, Action, Adventure | C19: =IFERROR(__xludf.DUMMYFUNCTION("ARRAYFORMULA(TRIM(SPLIT(B19, "",""))) "),"Animation") -> Animation | D19: =IFERROR(__xludf.DUMMYFUNCTION("""COMPUTED_VALUE"""),"Action") -> Action | E19: =IFERROR(__xludf.DUMMYFUNCTION("""COMPUTED_VALUE"""),"Adventure") -> Adventure | G19: =IFERROR(__xludf.DUMMYFUNCTION("""COMPUTED_VALUE"""),"Romance") -> Romance | H19: =COUNTIF(C19:E1002, G19) -> 14 | J19: 1.8 | K19: =COUNTIFS(Movies[Final Score], "<" & J19, Movies[Final Score], ">=" & J18) -> 0 | S19: =IFERROR(__xludf.DUMMYFUNCTION("""COMPUTED_VALUE"""),45707.0) -> 45707 | T19: =COUNTIF(Movies!N:N, S19) -> 1 | U19: =SUM($T$2:T19) -> 117 | W19: =IFERROR(__xludf.DUMMYFUNCTION("""COMPUTED_VALUE"""),36175.0) -> 36175 | X19: =IFERROR(__xludf.DUMMYFUNCTION("FILTER( Movies!F19:F1000, DATEVALUE(Movies!B19:B1000) = W19 ) "),8.683333333333332) -> 8.6833333
B20: =Movies!C20 -> Crime, Drama, Thriller | C20: =IFERROR(__xludf.DUMMYFUNCTION("ARRAYFORMULA(TRIM(SPLIT(B20, "",""))) "),"Crime") -> Crime | D20: =IFERROR(__xludf.DUMMYFUNCTION("""COMPUTED_VALUE"""),"Drama") -> Drama | E20: =IFERROR(__xludf.DUMMYFUNCTION("""COMPUTED_VALUE"""),"Thriller") -> Thriller | G20: =IFERROR(__xludf.DUMMYFUNCTION("""COMPUTED_VALUE"""),"Sport") -> Sport | H20: =COUNTIF(C20:E1003, G20) -> 3 | J20: 1.9 | K20: =COUNTIFS(Movies[Final Score], "<" & J20, Movies[Final Score], ">=" & J19) -> 0 | S20: =IFERROR(__xludf.DUMMYFUNCTION("""COMPUTED_VALUE"""),45712.0) -> 45712 | T20: =COUNTIF(Movies!N:N, S20) -> 1 | U20: =SUM($T$2:T20) -> 118 | W20: =IFERROR(__xludf.DUMMYFUNCTION("""COMPUTED_VALUE"""),36250.0) -> 36250 | X20: =IFERROR(__xludf.DUMMYFUNCTION("FILTER( Movies!F20:F1000, DATEVALUE(Movies!B20:B1000) = W20 ) "),8.216666666666667) -> 8.2166667
B21: =Movies!C21 -> Action, Adventure, Fantasy | C21: =IFERROR(__xludf.DUMMYFUNCTION("ARRAYFORMULA(TRIM(SPLIT(B21, "",""))) "),"Action") -> Action | D21: =IFERROR(__xludf.DUMMYFUNCTION("""COMPUTED_VALUE"""),"Adventure") -> Adventure | E21: =IFERROR(__xludf.DUMMYFUNCTION("""COMPUTED_VALUE"""),"Fantasy") -> Fantasy | G21: =IFERROR(__xludf.DUMMYFUNCTION("""COMPUTED_VALUE"""),"Family") -> Family | J21: 2 | K21: =COUNTIFS(Movies[Final Score], "<" & J21, Movies[Final Score], ">=" & J20) -> 0 | S21: =IFERROR(__xludf.DUMMYFUNCTION("""COMPUTED_VALUE"""),45717.0) -> 45717 | T21: =COUNTIF(Movies!N:N, S21) -> 1 | U21: =SUM($T$2:T21) -> 119 | W21: =IFERROR(__xludf.DUMMYFUNCTION("""COMPUTED_VALUE"""),36287.0) -> 36287 | X21: =IFERROR(__xludf.DUMMYFUNCTION("FILTER( Movies!F21:F1000, DATEVALUE(Movies!B21:B1000) = W21 ) "),5.916666666666667) -> 5.9166667
B22: =Movies!C22 -> Adventure, Comedy, Drama | C22: =IFERROR(__xludf.DUMMYFUNCTION("ARRAYFORMULA(TRIM(SPLIT(B22, "",""))) "),"Adventure") -> Adventure | D22: =IFERROR(__xludf.DUMMYFUNCTION("""COMPUTED_VALUE"""),"Comedy") -> Comedy | E22: =IFERROR(__xludf.DUMMYFUNCTION("""COMPUTED_VALUE"""),"Drama") -> Drama | G22: =IFERROR(__xludf.DUMMYFUNCTION("""COMPUTED_VALUE"""),"Musical") -> Musical | J22: 2.1 | K22: =COUNTIFS(Movies[Final Score], "<" & J22, Movies[Final Score], ">=" & J21) -> 0 | S22: =IFERROR(__xludf.DUMMYFUNCTION("""COMPUTED_VALUE"""),45726.0) -> 45726 | T22: =COUNTIF(Movies!N:N, S22) -> 1 | U22: =SUM($T$2:T22) -> 120 | W22: =IFERROR(__xludf.DUMMYFUNCTION("""COMPUTED_VALUE"""),36572.0) -> 36572 | X22: =IFERROR(__xludf.DUMMYFUNCTION("FILTER( Movies!F22:F1000, DATEVALUE(Movies!B22:B1000) = W22 ) "),6.733333333333333) -> 6.7333333
B23: =Movies!C23 -> Biography, Drama, History | C23: =IFERROR(__xludf.DUMMYFUNCTION("ARRAYFORMULA(TRIM(SPLIT(B23, "",""))) "),"Biography") -> Biography | D23: =IFERROR(__xludf.DUMMYFUNCTION("""COMPUTED_VALUE"""),"Drama") -> Drama | E23: =IFERROR(__xludf.DUMMYFUNCTION("""COMPUTED_VALUE"""),"History") -> History | G23: =IFERROR(__xludf.DUMMYFUNCTION("""COMPUTED_VALUE"""),"Documentary") -> Documentary | J23: 2.2 | K23: =COUNTIFS(Movies[Final Score], "<" & J23, Movies[Final Score], ">=" & J22) -> 0 | S23: =IFERROR(__xludf.DUMMYFUNCTION("""COMPUTED_VALUE"""),45729.0) -> 45729 | T23: =COUNTIF(Movies!N:N, S23) -> 1 | U23: =SUM($T$2:T23) -> 121 | W23: =IFERROR(__xludf.DUMMYFUNCTION("""COMPUTED_VALUE"""),36602.0) -> 36602 | X23: =IFERROR(__xludf.DUMMYFUNCTION("FILTER( Movies!F23:F1000, DATEVALUE(Movies!B23:B1000) = W23 ) "),6.333333333333332) -> 6.3333333
B24: =Movies!C24 -> Action, Adventure, Sci-Fi | C24: =IFERROR(__xludf.DUMMYFUNCTION("ARRAYFORMULA(TRIM(SPLIT(B24, "",""))) "),"Action") -> Action | D24: =IFERROR(__xludf.DUMMYFUNCTION("""COMPUTED_VALUE"""),"Adventure") -> Adventure | E24: =IFERROR(__xludf.DUMMYFUNCTION("""COMPUTED_VALUE"""),"Sci-Fi") -> Sci-Fi | G24: =IFERROR(__xludf.DUMMYFUNCTION("""COMPUTED_VALUE"""),"") | J24: 2.3 | K24: =COUNTIFS(Movies[Final Score], "<" & J24, Movies[Final Score], ">=" & J23) -> 0 | S24: =IFERROR(__xludf.DUMMYFUNCTION("""COMPUTED_VALUE"""),45747.0) -> 45747 | T24: =COUNTIF(Movies!N:N, S24) -> 1 | U24: =SUM($T$2:T24) -> 122 | W24: =IFERROR(__xludf.DUMMYFUNCTION("""COMPUTED_VALUE"""),36651.0) -> 36651 | X24: =IFERROR(__xludf.DUMMYFUNCTION("FILTER( Movies!F24:F1000, DATEVALUE(Movies!B24:B1000) = W24 ) "),"#N/A") -> #N/A
B25: =Movies!C25 -> Adventure, Drama, Fantasy | C25: =IFERROR(__xludf.DUMMYFUNCTION("ARRAYFORMULA(TRIM(SPLIT(B25, "",""))) "),"Adventure") -> Adventure | D25: =IFERROR(__xludf.DUMMYFUNCTION("""COMPUTED_VALUE"""),"Drama") -> Drama | E25: =IFERROR(__xludf.DUMMYFUNCTION("""COMPUTED_VALUE"""),"Fantasy") -> Fantasy | G25: =IFERROR(__xludf.DUMMYFUNCTION("""COMPUTED_VALUE"""),"#VALUE!") -> #VALUE! | J25: 2.4 | K25: =COUNTIFS(Movies[Final Score], "<" & J25, Movies[Final Score], ">=" & J24) -> 0 | S25: =IFERROR(__xludf.DUMMYFUNCTION("""COMPUTED_VALUE"""),45751.0) -> 45751 | T25: =COUNTIF(Movies!N:N, S25) -> 1 | U25: =SUM($T$2:T25) -> 123 | W25: =IFERROR(__xludf.DUMMYFUNCTION("""COMPUTED_VALUE"""),36749.0) -> 36749 | X25: =IFERROR(__xludf.DUMMYFUNCTION("FILTER( Movies!F25:F1000, DATEVALUE(Movies!B25:B1000) = W25 ) "),5.3999999999999995) -> 5.4
B26: =Movies!C26 -> Action, Drama, Horror | C26: =IFERROR(__xludf.DUMMYFUNCTION("ARRAYFORMULA(TRIM(SPLIT(B26, "",""))) "),"Action") -> Action | D26: =IFERROR(__xludf.DUMMYFUNCTION("""COMPUTED_VALUE"""),"Drama") -> Drama | E26: =IFERROR(__xludf.DUMMYFUNCTION("""COMPUTED_VALUE"""),"Horror") -> Horror | J26: 2.5 | K26: =COUNTIFS(Movies[Final Score], "<" & J26, Movies[Final Score], ">=" & J25) -> 0 | S26: =IFERROR(__xludf.DUMMYFUNCTION("""COMPUTED_VALUE"""),45765.0) -> 45765 | T26: =COUNTIF(Movies!N:N, S26) -> 1 | U26: =SUM($T$2:T26) -> 124 | W26: =IFERROR(__xludf.DUMMYFUNCTION("""COMPUTED_VALUE"""),37036.0) -> 37036 | X26: =IFERROR(__xludf.DUMMYFUNCTION("FILTER( Movies!F26:F1000, DATEVALUE(Movies!B26:B1000) = W26 ) "),7.833333333333333) -> 7.8333333
B27: =Movies!C27 -> Action, Biography, Drama | C27: =IFERROR(__xludf.DUMMYFUNCTION("ARRAYFORMULA(TRIM(SPLIT(B27, "",""))) "),"Action") -> Action | D27: =IFERROR(__xludf.DUMMYFUNCTION("""COMPUTED_VALUE"""),"Biography") -> Biography | E27: =IFERROR(__xludf.DUMMYFUNCTION("""COMPUTED_VALUE"""),"Drama") -> Drama | J27: 2.6 | K27: =COUNTIFS(Movies[Final Score], "<" & J27, Movies[Final Score], ">=" & J26) -> 0 | S27: =IFERROR(__xludf.DUMMYFUNCTION("""COMPUTED_VALUE"""),45778.0) -> 45778 | T27: =COUNTIF(Movies!N:N, S27) -> 1 | U27: =SUM($T$2:T27) -> 125 | W27: =IFERROR(__xludf.DUMMYFUNCTION("""COMPUTED_VALUE"""),37211.0) -> 37211 | X27: =IFERROR(__xludf.DUMMYFUNCTION("FILTER( Movies!F27:F1000, DATEVALUE(Movies!B27:B1000) = W27 ) "),8.0) -> 8
B28: =Movies!C28 -> Adventure, Drama, Sci-Fi | C28: =IFERROR(__xludf.DUMMYFUNCTION("ARRAYFORMULA(TRIM(SPLIT(B28, "",""))) "),"Adventure") -> Adventure | D28: =IFERROR(__xludf.DUMMYFUNCTION("""COMPUTED_VALUE"""),"Drama") -> Drama | E28: =IFERROR(__xludf.DUMMYFUNCTION("""COMPUTED_VALUE"""),"Sci-Fi") -> Sci-Fi | J28: 2.7 | K28: =COUNTIFS(Movies[Final Score], "<" & J28, Movies[Final Score], ">=" & J27) -> 0 | S28: =IFERROR(__xludf.DUMMYFUNCTION("""COMPUTED_VALUE"""),45789.0) -> 45789 | T28: =COUNTIF(Movies!N:N, S28) -> 1 | U28: =SUM($T$2:T28) -> 126 | W28: =IFERROR(__xludf.DUMMYFUNCTION("""COMPUTED_VALUE"""),37232.0) -> 37232 | X28: =IFERROR(__xludf.DUMMYFUNCTION("FILTER( Movies!F28:F1000, DATEVALUE(Movies!B28:B1000) = W28 ) "),6.949999999999999) -> 6.95
B29: =Movies!C29 -> Animation, Action, Adventure | C29: =IFERROR(__xludf.DUMMYFUNCTION("ARRAYFORMULA(TRIM(SPLIT(B29, "",""))) "),"Animation") -> Animation | D29: =IFERROR(__xludf.DUMMYFUNCTION("""COMPUTED_VALUE"""),"Action") -> Action | E29: =IFERROR(__xludf.DUMMYFUNCTION("""COMPUTED_VALUE"""),"Adventure") -> Adventure | H29: =COUNTIF(C29:E1000, G29) -> 0 | J29: 2.8 | K29: =COUNTIFS(Movies[Final Score], "<" & J29, Movies[Final Score], ">=" & J28) -> 1 | S29: =IFERROR(__xludf.DUMMYFUNCTION("""COMPUTED_VALUE"""),45801.0) -> 45801 | T29: =COUNTIF(Movies!N:N, S29) -> 1 | U29: =SUM($T$2:T29) -> 127 | W29: =IFERROR(__xludf.DUMMYFUNCTION("""COMPUTED_VALUE"""),37244.0) -> 37244 | X29: =IFERROR(__xludf.DUMMYFUNCTION("FILTER( Movies!F29:F1000, DATEVALUE(Movies!B29:B1000) = W29 ) "),8.899999999999999) -> 8.9
B30: =Movies!C30 -> Action, Sci-Fi, Thriller | C30: =IFERROR(__xludf.DUMMYFUNCTION("ARRAYFORMULA(TRIM(SPLIT(B30, "",""))) "),"Action") -> Action | D30: =IFERROR(__xludf.DUMMYFUNCTION("""COMPUTED_VALUE"""),"Sci-Fi") -> Sci-Fi | E30: =IFERROR(__xludf.DUMMYFUNCTION("""COMPUTED_VALUE"""),"Thriller") -> Thriller | H30: =COUNTIF(C30:E1001, G30) -> 0 | J30: 2.9 | K30: =COUNTIFS(Movies[Final Score], "<" & J30, Movies[Final Score], ">=" & J29) -> 0 | S30: =IFERROR(__xludf.DUMMYFUNCTION("""COMPUTED_VALUE"""),45808.0) -> 45808 | T30: =COUNTIF(Movies!N:N, S30) -> 2 | U30: =SUM($T$2:T30) -> 129 | W30: =IFERROR(__xludf.DUMMYFUNCTION("""COMPUTED_VALUE"""),37274.0) -> 37274 | X30: =IFERROR(__xludf.DUMMYFUNCTION("FILTER( Movies!F30:F1000, DATEVALUE(Movies!B30:B1000) = W30 ) "),7.333333333333333) -> 7.3333333
B31: =Movies!C31 -> Drama, Romance | C31: =IFERROR(__xludf.DUMMYFUNCTION("ARRAYFORMULA(TRIM(SPLIT(B31, "",""))) "),"Drama") -> Drama | D31: =IFERROR(__xludf.DUMMYFUNCTION("""COMPUTED_VALUE"""),"Romance") -> Romance | H31: =COUNTIF(C31:E1002, G31) -> 0 | J31: 3 | K31: =COUNTIFS(Movies[Final Score], "<" & J31, Movies[Final Score], ">=" & J30) -> 0 | S31: =IFERROR(__xludf.DUMMYFUNCTION("""COMPUTED_VALUE"""),45820.0) -> 45820 | T31: =COUNTIF(Movies!N:N, S31) -> 1 | U31: =SUM($T$2:T31) -> 130 | W31: =IFERROR(__xludf.DUMMYFUNCTION("""COMPUTED_VALUE"""),37379.0) -> 37379 | X31: =IFERROR(__xludf.DUMMYFUNCTION("FILTER( Movies!F31:F1000, DATEVALUE(Movies!B31:B1000) = W31 ) "),7.449999999999999) -> 7.45
B32: =Movies!C32 -> Action, Crime, Drama | C32: =IFERROR(__xludf.DUMMYFUNCTION("ARRAYFORMULA(TRIM(SPLIT(B32, "",""))) "),"Action") -> Action | D32: =IFERROR(__xludf.DUMMYFUNCTION("""COMPUTED_VALUE"""),"Crime") -> Crime | E32: =IFERROR(__xludf.DUMMYFUNCTION("""COMPUTED_VALUE"""),"Drama") -> Drama | H32: =COUNTIF(C32:E1003, G32) -> 0 | J32: 3.1 | K32: =COUNTIFS(Movies[Final Score], "<" & J32, Movies[Final Score], ">=" & J31) -> 0 | S32: =IFERROR(__xludf.DUMMYFUNCTION("""COMPUTED_VALUE"""),45846.0) -> 45846 | T32: =COUNTIF(Movies!N:N, S32) -> 3 | U32: =SUM($T$2:T32) -> 133 | W32: =IFERROR(__xludf.DUMMYFUNCTION("""COMPUTED_VALUE"""),37421.0) -> 37421 | X32: =IFERROR(__xludf.DUMMYFUNCTION("FILTER( Movies!F32:F1000, DATEVALUE(Movies!B32:B1000) = W32 ) "),7.8) -> 7.8
B33: =Movies!C33 -> Adventure, Drama, Fantasy | C33: =IFERROR(__xludf.DUMMYFUNCTION("ARRAYFORMULA(TRIM(SPLIT(B33, "",""))) "),"Adventure") -> Adventure | D33: =IFERROR(__xludf.DUMMYFUNCTION("""COMPUTED_VALUE"""),"Drama") -> Drama | E33: =IFERROR(__xludf.DUMMYFUNCTION("""COMPUTED_VALUE"""),"Fantasy") -> Fantasy | J33: 3.2 | K33: =COUNTIFS(Movies[Final Score], "<" & J33, Movies[Final Score], ">=" & J32) -> 0 | S33: =IFERROR(__xludf.DUMMYFUNCTION("""COMPUTED_VALUE"""),45849.0) -> 45849 | T33: =COUNTIF(Movies!N:N, S33) -> 2 | U33: =SUM($T$2:T33) -> 135 | W33: =IFERROR(__xludf.DUMMYFUNCTION("""COMPUTED_VALUE"""),37575.0) -> 37575 | X33: =IFERROR(__xludf.DUMMYFUNCTION("FILTER( Movies!F33:F1000, DATEVALUE(Movies!B33:B1000) = W33 ) "),8.133333333333333) -> 8.1333333
B34: =Movies!C34 -> Crime, Drama, Mystery | C34: =IFERROR(__xludf.DUMMYFUNCTION("ARRAYFORMULA(TRIM(SPLIT(B34, "",""))) "),"Crime") -> Crime | D34: =IFERROR(__xludf.DUMMYFUNCTION("""COMPUTED_VALUE"""),"Drama") -> Drama | E34: =IFERROR(__xludf.DUMMYFUNCTION("""COMPUTED_VALUE"""),"Mystery") -> Mystery | J34: 3.3 | K34: =COUNTIFS(Movies[Final Score], "<" & J34, Movies[Final Score], ">=" & J33) -> 0 | S34: =IFERROR(__xludf.DUMMYFUNCTION("""COMPUTED_VALUE"""),45855.0) -> 45855 | T34: =COUNTIF(Movies!N:N, S34) -> 1 | U34: =SUM($T$2:T34) -> 136 | W34: =IFERROR(__xludf.DUMMYFUNCTION("""COMPUTED_VALUE"""),37608.0) -> 37608 | X34: =IFERROR(__xludf.DUMMYFUNCTION("FILTER( Movies!F34:F1000, DATEVALUE(Movies!B34:B1000) = W34 ) "),"#N/A") -> #N/A
B35: =Movies!C35 -> Action, Crime, Drama | C35: =IFERROR(__xludf.DUMMYFUNCTION("ARRAYFORMULA(TRIM(SPLIT(B35, "",""))) "),"Action") -> Action | D35: =IFERROR(__xludf.DUMMYFUNCTION("""COMPUTED_VALUE"""),"Crime") -> Crime | E35: =IFERROR(__xludf.DUMMYFUNCTION("""COMPUTED_VALUE"""),"Drama") -> Drama | J35: 3.4 | K35: =COUNTIFS(Movies[Final Score], "<" & J35, Movies[Final Score], ">=" & J34) -> 0 | S35: =IFERROR(__xludf.DUMMYFUNCTION("""COMPUTED_VALUE"""),45858.0) -> 45858 | T35: =COUNTIF(Movies!N:N, S35) -> 2 | U35: =SUM($T$2:T35) -> 138 | W35: =IFERROR(__xludf.DUMMYFUNCTION("""COMPUTED_VALUE"""),37615.0) -> 37615 | X35: =IFERROR(__xludf.DUMMYFUNCTION("FILTER( Movies!F35:F1000, DATEVALUE(Movies!B35:B1000) = W35 ) "),8.499999999999998) -> 8.5
B36: =Movies!C36 -> Drama, War | C36: =IFERROR(__xludf.DUMMYFUNCTION("ARRAYFORMULA(TRIM(SPLIT(B36, "",""))) "),"Drama") -> Drama | D36: =IFERROR(__xludf.DUMMYFUNCTION("""COMPUTED_VALUE"""),"War") -> War | J36: 3.5 | K36: =COUNTIFS(Movies[Final Score], "<" & J36, Movies[Final Score], ">=" & J35) -> 1 | S36: =IFERROR(__xludf.DUMMYFUNCTION("""COMPUTED_VALUE"""),45861.0) -> 45861 | T36: =COUNTIF(Movies!N:N, S36) -> 3 | U36: =SUM($T$2:T36) -> 141 | W36: =IFERROR(__xludf.DUMMYFUNCTION("""COMPUTED_VALUE"""),37652.0) -> 37652 | X36: =IFERROR(__xludf.DUMMYFUNCTION("FILTER( Movies!F36:F1000, DATEVALUE(Movies!B36:B1000) = W36 ) "),6.6000000000000005) -> 6.6
B37: =Movies!C37 -> Drama, Romance | C37: =IFERROR(__xludf.DUMMYFUNCTION("ARRAYFORMULA(TRIM(SPLIT(B37, "",""))) "),"Drama") -> Drama | D37: =IFERROR(__xludf.DUMMYFUNCTION("""COMPUTED_VALUE"""),"Romance") -> Romance | J37: 3.6 | K37: =COUNTIFS(Movies[Final Score], "<" & J37, Movies[Final Score], ">=" & J36) -> 1 | S37: =IFERROR(__xludf.DUMMYFUNCTION("""COMPUTED_VALUE"""),45863.0) -> 45863 | T37: =COUNTIF(Movies!N:N, S37) -> 4 | U37: =SUM($T$2:T37) -> 145 | W37: =IFERROR(__xludf.DUMMYFUNCTION("""COMPUTED_VALUE"""),37743.0) -> 37743 | X37: =IFERROR(__xludf.DUMMYFUNCTION("FILTER( Movies!F37:F1000, DATEVALUE(Movies!B37:B1000) = W37 ) "),"#N/A") -> #N/A
B38: =Movies!C38 -> Action, Adventure, Sci-Fi | C38: =IFERROR(__xludf.DUMMYFUNCTION("ARRAYFORMULA(TRIM(SPLIT(B38, "",""))) "),"Action") -> Action | D38: =IFERROR(__xludf.DUMMYFUNCTION("""COMPUTED_VALUE"""),"Adventure") -> Adventure | E38: =IFERROR(__xludf.DUMMYFUNCTION("""COMPUTED_VALUE"""),"Sci-Fi") -> Sci-Fi | J38: 3.7 | K38: =COUNTIFS(Movies[Final Score], "<" & J38, Movies[Final Score], ">=" & J37) -> 0 | S38: =IFERROR(__xludf.DUMMYFUNCTION("""COMPUTED_VALUE"""),45864.0) -> 45864 | T38: =COUNTIF(Movies!N:N, S38) -> 1 | U38: =SUM($T$2:T38) -> 146 | W38: =IFERROR(__xludf.DUMMYFUNCTION("""COMPUTED_VALUE"""),37764.0) -> 37764 | X38: =IFERROR(__xludf.DUMMYFUNCTION("FILTER( Movies!F38:F1000, DATEVALUE(Movies!B38:B1000) = W38 ) "),6.866666666666667) -> 6.8666667
B39: =Movies!C39 -> Drama, Romance, Sci-Fi | C39: =IFERROR(__xludf.DUMMYFUNCTION("ARRAYFORMULA(TRIM(SPLIT(B39, "",""))) "),"Drama") -> Drama | D39: =IFERROR(__xludf.DUMMYFUNCTION("""COMPUTED_VALUE"""),"Romance") -> Romance | E39: =IFERROR(__xludf.DUMMYFUNCTION("""COMPUTED_VALUE"""),"Sci-Fi") -> Sci-Fi | J39: 3.8 | K39: =COUNTIFS(Movies[Final Score], "<" & J39, Movies[Final Score], ">=" & J38) -> 0 | S39: =IFERROR(__xludf.DUMMYFUNCTION("""COMPUTED_VALUE"""),45865.0) -> 45865 | T39: =COUNTIF(Movies!N:N, S39) -> 1 | U39: =SUM($T$2:T39) -> 147 | W39: =IFERROR(__xludf.DUMMYFUNCTION("""COMPUTED_VALUE"""),37799.0) -> 37799 | X39: =IFERROR(__xludf.DUMMYFUNCTION("FILTER( Movies!F39:F1000, DATEVALUE(Movies!B39:B1000) = W39 ) "),5.916666666666667) -> 5.9166667
B40: =Movies!C40 -> Action, Drama, Mystery | C40: =IFERROR(__xludf.DUMMYFUNCTION("ARRAYFORMULA(TRIM(SPLIT(B40, "",""))) "),"Action") -> Action | D40: =IFERROR(__xludf.DUMMYFUNCTION("""COMPUTED_VALUE"""),"Drama") -> Drama | E40: =IFERROR(__xludf.DUMMYFUNCTION("""COMPUTED_VALUE"""),"Mystery") -> Mystery | J40: 3.9 | K40: =COUNTIFS(Movies[Final Score], "<" & J40, Movies[Final Score], ">=" & J39) -> 0 | S40: =IFERROR(__xludf.DUMMYFUNCTION("""COMPUTED_VALUE"""),45868.0) -> 45868 | T40: =COUNTIF(Movies!N:N, S40) -> 2 | U40: =SUM($T$2:T40) -> 149 | W40: =IFERROR(__xludf.DUMMYFUNCTION("""COMPUTED_VALUE"""),37883.0) -> 37883 | X40: =IFERROR(__xludf.DUMMYFUNCTION("FILTER( Movies!F40:F1000, DATEVALUE(Movies!B40:B1000) = W40 ) "),6.216666666666666) -> 6.2166667
...
